Traceback (most recent call last):
  File "/Library/Frameworks/Python.framework/Versions/3.10/bin/uvicorn", line 8, in <module>
    sys.exit(main())
  File "/Library/Frameworks/Python.framework/Versions/3.10/lib/python3.10/site-packages/click/core.py", line 1130, in __call__
    return self.main(*args, **kwargs)
  File "/Library/Frameworks/Python.framework/Versions/3.10/lib/python3.10/site-packages/click/core.py", line 1055, in main
    rv = self.invoke(ctx)
  File "/Library/Frameworks/Python.framework/Versions/3.10/lib/python3.10/site-packages/click/core.py", line 1404, in invoke
    return ctx.invoke(self.callback, **ctx.params)
  File "/Library/Frameworks/Python.framework/Versions/3.10/lib/python3.10/site-packages/click/core.py", line 760, in invoke
    return __callback(*args, **kwargs)
  File "/Library/Frameworks/Python.framework/Versions/3.10/lib/python3.10/site-packages/uvicorn/main.py", line 437, in main
    run(app, **kwargs)
  File "/Library/Frameworks/Python.framework/Versions/3.10/lib/python3.10/site-packages/uvicorn/main.py", line 463, in run
    server.run()
  File "/Library/Frameworks/Python.framework/Versions/3.10/lib/python3.10/site-packages/uvicorn/server.py", line 60, in run
    return asyncio.run(self.serve(sockets=sockets))
  File "/Library/Frameworks/Python.framework/Versions/3.10/lib/python3.10/asyncio/runners.py", line 44, in run
    return loop.run_until_complete(main)
  File "/Library/Frameworks/Python.framework/Versions/3.10/lib/python3.10/asyncio/base_events.py", line 641, in run_until_complete
    return future.result()
  File "/Library/Frameworks/Python.framework/Versions/3.10/lib/python3.10/site-packages/uvicorn/server.py", line 67, in serve
    config.load()
  File "/Library/Frameworks/Python.framework/Versions/3.10/lib/python3.10/site-packages/uvicorn/config.py", line 458, in load
    self.loaded_app = import_from_string(self.app)
  File "/Library/Frameworks/Python.framework/Versions/3.10/lib/python3.10/site-packages/uvicorn/importer.py", line 21, in import_from_string
    module = importlib.import_module(module_str)
  File "/Library/Frameworks/Python.framework/Versions/3.10/lib/python3.10/importlib/__init__.py", line 126, in import_module
    return _bootstrap._gcd_import(name[level:], package, level)
  File "<frozen importlib._bootstrap>", line 1050, in _gcd_import
  File "<frozen importlib._bootstrap>", line 1027, in _find_and_load
  File "<frozen importlib._bootstrap>", line 1006, in _find_and_load_unlocked
  File "<frozen importlib._bootstrap>", line 688, in _load_unlocked
  File "<frozen importlib._bootstrap_external>", line 883, in exec_module
  File "<frozen importlib._bootstrap>", line 241, in _call_with_frames_removed
  File "/Users/ngzen/Desktop/python_test/fastapi/./main.py", line 11, in <module>
    users = db.Table('Users', metadata, autoload=True, autoload_with=engine)
  File "<string>", line 2, in __new__
  File "/Library/Frameworks/Python.framework/Versions/3.10/lib/python3.10/site-packages/sqlalchemy/util/deprecations.py", line 309, in warned
    return fn(*args, **kwargs)
  File "/Library/Frameworks/Python.framework/Versions/3.10/lib/python3.10/site-packages/sqlalchemy/sql/schema.py", line 606, in __new__
    with util.safe_reraise():
  File "/Library/Frameworks/Python.framework/Versions/3.10/lib/python3.10/site-packages/sqlalchemy/util/langhelpers.py", line 70, in __exit__
    compat.raise_(
  File "/Library/Frameworks/Python.framework/Versions/3.10/lib/python3.10/site-packages/sqlalchemy/util/compat.py", line 207, in raise_
    raise exception
  File "/Library/Frameworks/Python.framework/Versions/3.10/lib/python3.10/site-packages/sqlalchemy/sql/schema.py", line 602, in __new__
    table._init(name, metadata, *args, **kw)
  File "/Library/Frameworks/Python.framework/Versions/3.10/lib/python3.10/site-packages/sqlalchemy/sql/schema.py", line 677, in _init
    self._autoload(
  File "/Library/Frameworks/Python.framework/Versions/3.10/lib/python3.10/site-packages/sqlalchemy/sql/schema.py", line 712, in _autoload
    conn_insp.reflect_table(
  File "/Library/Frameworks/Python.framework/Versions/3.10/lib/python3.10/site-packages/sqlalchemy/engine/reflection.py", line 789, in reflect_table
    raise exc.NoSuchTableError(table_name)
sqlalchemy.exc.NoSuchTableError: Users
